Workbook
Name Slicer_Representative: #N/A

Sheet pivots
A3: call count | B3: Total Amount | C3: Sum of Duration | D3: Avg Rating | E3: 5*Calls
A4: 1000 | B4: 96623 | C4: 89850 | D4: 3.8854 | E4: 307
A7: call count | B7: Total Amount | C7: Sum of Duration | D7: Avg Rating | E7: 5*Calls
A8: 186 | B8: 16651 | C8: 17807 | D8: 3.8973118 | E8: 62
A24: Row Labels | B24: call count | C24: call count2 | G24: Row Labels | H24: call count
A25: Jan | B25: 10 | C25: 10 | G25: Saturday | H25: 34
A26: Feb | B26: 11 | C26: 11 | G26: Friday | H26: 29
A27: Mar | B27: 30 | C27: 30 | G27: Thursday | H27: 18
A28: Apr | B28: 23 | C28: 23 | G28: Wednesday | H28: 29
A29: May | B29: 22 | C29: 22 | G29: Tuesday | H29: 28
A30: Jun | B30: 11 | C30: 11 | G30: Monday | H30: 23
A31: Jul | B31: 17 | C31: 17 | G31: Sunday | H31: 25
A32: Aug | B32: 12 | C32: 12 | G32: Grand Total | H32: 186
A33: Sep | B33: 13 | C33: 13
A34: Oct | B34: 15 | C34: 15
A35: Nov | B35: 8 | C35: 8
A36: Dec | B36: 14 | C36: 14
A37: Grand Total | B37: 186 | C37: 186
F43: call count | G43: Column Labels
F44: Row Labels | G44: Female | H44: Male | I44: Grand Total
F45: Cincinnati | G45: 144 | H45: 132 | I45: 276
F46: Cleveland | G46: 326 | H46: 63 | I46: 389
F47: Columbus | G47: 129 | H47: 206 | I47: 335
F48: Grand Total | G48: 599 | H48: 401 | I48: 1000
F61: For Graph | I61: selected rep | J61: =pivots!A75 -> R04
F62: Rep | G62: Calls | H62: Amount | I62: sel.calls | J62: sel.Amount
A63: Row Labels | B63: call count | C63: Total Amount | F63: {=A64:C68} -> R01 | G63: 189 | H63: 18415 | I63: =IF(F63=$J$61,G63,NA()) -> #N/A | J63: =IF(F63=$J$61,H63,NA()) -> #N/A
A64: R01 | B64: 189 | C64: 18415 | F64: R02 | G64: 218 | H64: 20581 | I64: =IF(F64=$J$61,G64,NA()) -> #N/A | J64: =IF(F64=$J$61,H64,NA()) -> #N/A
A65: R02 | B65: 218 | C65: 20581 | F65: R03 | G65: 207 | H65: 20872 | I65: =IF(F65=$J$61,G65,NA()) -> #N/A | J65: =IF(F65=$J$61,H65,NA()) -> #N/A
A66: R03 | B66: 207 | C66: 20872 | F66: R04 | G66: 186 | H66: 16651 | I66: =IF(F66=$J$61,G66,NA()) -> 186 | J66: =IF(F66=$J$61,H66,NA()) -> 16651
A67: R04 | B67: 186 | C67: 16651 | F67: R05 | G67: 200 | H67: 20104 | I67: =IF(F67=$J$61,G67,NA()) -> #N/A | J67: =IF(F67=$J$61,H67,NA()) -> #N/A
A68: R05 | B68: 200 | C68: 20104
A69: Grand Total | B69: 1000 | C69: 96623
A74: Row Labels | G74: Rep Summary
A75: R04 | G75: %of calls | H75: =A8/A4 -> 0.186
G76: call rank | H76: =_xlfn.XLOOKUP(A75,F63:F67,G63:G67) -> 186
G77: Amount rank | H77: =_xlfn.XLOOKUP(A75,F63:F67,H63:H67) -> 16651
G80: call rank | H80: =_xlfn.RANK.AVG(H76,G63:G67) -> 5
G81: Amount rank | H81: =_xlfn.RANK.AVG(H77,H63:H67) -> 5
G83: Labels:
...

Sheet Data
B1: Call Centre Data
B3: Call number | C3: Customer ID | D3: Duration | E3: Representative | F3: Date of Call | G3: Purchase Amount | H3: Satisfaction Rating | I3: FY | J3: Day of week | K3: Duration Bucket | L3: Rating rounded | Q3: Customer ID | R3: Gedner | S3: Age | T3: City
B4: Call_7271 | C4: C0003 | D4: 116 | E4: R05 | F4: 44927 | G4: 128 | H4: 4.9 | I4: =IF(MONTH(calls[[#This Row],[Date of Call]])<=6, YEAR(calls[[#This Row],[Date of Call]]), YEAR(calls[[#This Row],[Date of Call]])+1) -> 2023 | J4: =TEXT(calls[[#This Row],[Date of Call]],"DDDD") -> Sunday | K4: {=_xlfn.IFS(calls[[#This Row],[Duration]]<=10,"Under 10 mins", calls[[#This Row],[Duration]]<=30, "10 to 30 mins", calls[[#This Row],[Duration]]<=60, "30 to 60 mins", calls[[#This Row],[Duration]]<=120, "1 to 2 hours", TRUE, "More than 2 hours")} -> 1 to 2 hours | L4: =ROUND(calls[[#This Row],[Satisfaction Rating]],0) -> 5 | Q4: C0001 | R4: Male | S4: 41 | T4: Columbus
B5: Call_7272 | C5: C0004 | D5: 119 | E5: R05 | F5: 44927 | G5: 135 | H5: 2.9 | I5: =IF(MONTH(calls[[#This Row],[Date of Call]])<=6, YEAR(calls[[#This Row],[Date of Call]]), YEAR(calls[[#This Row],[Date of Call]])+1) -> 2023 | J5: =TEXT(calls[[#This Row],[Date of Call]],"DDDD") -> Sunday | K5: {=_xlfn.IFS(calls[[#This Row],[Duration]]<=10,"Under 10 mins", calls[[#This Row],[Duration]]<=30, "10 to 30 mins", calls[[#This Row],[Duration]]<=60, "30 to 60 mins", calls[[#This Row],[Duration]]<=120, "1 to 2 hours", TRUE, "More than 2 hours")} -> 1 to 2 hours | L5: =ROUND(calls[[#This Row],[Satisfaction Rating]],0) -> 3 | Q5: C0002 | R5: Male | S5: 31 | T5: Cleveland
B6: Call_7273 | C6: C0005 | D6: 68 | E6: R02 | F6: 44927 | G6: 66 | H6: 4.7 | I6: =IF(MONTH(calls[[#This Row],[Date of Call]])<=6, YEAR(calls[[#This Row],[Date of Call]]), YEAR(calls[[#This Row],[Date of Call]])+1) -> 2023 | J6: =TEXT(calls[[#This Row],[Date of Call]],"DDDD") -> Sunday | K6: {=_xlfn.IFS(calls[[#This Row],[Duration]]<=10,"Under 10 mins", calls[[#This Row],[Duration]]<=30, "10 to 30 mins", calls[[#This Row],[Duration]]<=60, "30 to 60 mins", calls[[#This Row],[Duration]]<=120, "1 to 2 hours", TRUE, "More than 2 hours")} -> 1 to 2 hours | L6: =ROUND(calls[[#This Row],[Satisfaction Rating]],0) -> 5 | Q6: C0003 | R6: Male | S6: 26 | T6: Cincinnati
B7: Call_7274 | C7: C0014 | D7: 119 | E7: R02 | F7: 44927 | G7: 22 | H7: 2.9 | I7: =IF(MONTH(calls[[#This Row],[Date of Call]])<=6, YEAR(calls[[#This Row],[Date of Call]]), YEAR(calls[[#This Row],[Date of Call]])+1) -> 2023 | J7: =TEXT(calls[[#This Row],[Date of Call]],"DDDD") -> Sunday | K7: {=_xlfn.IFS(calls[[#This Row],[Duration]]<=10,"Under 10 mins", calls[[#This Row],[Duration]]<=30, "10 to 30 mins", calls[[#This Row],[Duration]]<=60, "30 to 60 mins", calls[[#This Row],[Duration]]<=120, "1 to 2 hours", TRUE, "More than 2 hours")} -> 1 to 2 hours | L7: =ROUND(calls[[#This Row],[Satisfaction Rating]],0) -> 3 | Q7: C0004 | R7: Male | S7: 36 | T7: Cincinnati
B8: Call_7275 | C8: C0011 | D8: 128 | E8: R01 | F8: 44928 | G8: 31 | H8: 2.8 | I8: =IF(MONTH(calls[[#This Row],[Date of Call]])<=6, YEAR(calls[[#This Row],[Date of Call]]), YEAR(calls[[#This Row],[Date of Call]])+1) -> 2023 | J8: =TEXT(calls[[#This Row],[Date of Call]],"DDDD") -> Monday | K8: {=_xlfn.IFS(calls[[#This Row],[Duration]]<=10,"Under 10 mins", calls[[#This Row],[Duration]]<=30, "10 to 30 mins", calls[[#This Row],[Duration]]<=60, "30 to 60 mins", calls[[#This Row],[Duration]]<=120, "1 to 2 hours", TRUE, "More than 2 hours")} -> More than 2 hours | L8: =ROUND(calls[[#This Row],[Satisfaction Rating]],0) -> 3 | Q8: C0005 | R8: Male | S8: 37 | T8: Columbus
B9: Call_7276 | C9: C0011 | D9: 49 | E9: R02 | F9: 44929 | G9: 135 | H9: 4.8 | I9: =IF(MONTH(calls[[#This Row],[Date of Call]])<=6, YEAR(calls[[#This Row],[Date of Call]]), YEAR(calls[[#This Row],[Date of Call]])+1) -> 2023 | J9: =TEXT(calls[[#This Row],[Date of Call]],"DDDD") -> Tuesday | K9: {=_xlfn.IFS(calls[[#This Row],[Duration]]<=10,"Under 10 mins", calls[[#This Row],[Duration]]<=30, "10 to 30 mins", calls[[#This Row],[Duration]]<=60, "30 to 60 mins", calls[[#This Row],[Duration]]<=120, "1 to 2 hours", TRUE, "More than 2 hours")} -> 30 to 60 mins | L9: =ROUND(calls[[#This Row],[Satisfaction Rating]],0) -> 5 | Q9: C0006 | R9: Male | S9: 23 | T9: Columbus
B10: Call_7277 | C10: C0007 | D10: 84 | E10: R05 | F10: 44929 | G10: 60 | H10: 4.7 | I10: =IF(MONTH(calls[[#This Row],[Date of Call]])<=6, YEAR(calls[[#This Row],[Date of Call]]), YEAR(calls[[#This Row],[Date of Call]])+1) -> 2023 | J10: =TEXT(calls[[#This Row],[Date of Call]],"DDDD") -> Tuesday | K10: {=_xlfn.IFS(calls[[#This Row],[Duration]]<=10,"Under 10 mins", calls[[#This Row],[Duration]]<=30, "10 to 30 mins", calls[[#This Row],[Duration]]<=60, "30 to 60 mins", calls[[#This Row],[Duration]]<=120, "1 to 2 hours", TRUE, "More than 2 hours")} -> 1 to 2 hours | L10: =ROUND(calls[[#This Row],[Satisfaction Rating]],0) -> 5 | Q10: C0007 | R10: Female | S10: 22 | T10: Cleveland
B11: Call_7278 | C11: C0003 | D11: 103 | E11: R04 | F11: 44929 | G11: 148 | H11: 4.4 | I11: =IF(MONTH(calls[[#This Row],[Date of Call]])<=6, YEAR(calls[[#This Row],[Date of Call]]), YEAR(calls[[#This Row],[Date of Call]])+1) -> 2023 | J11: =TEXT(calls[[#This Row],[Date of Call]],"DDDD") -> Tuesday | K11: {=_xlfn.IFS(calls[[#This Row],[Duration]]<=10,"Under 10 mins", calls[[#This Row],[Duration]]<=30, "10 to 30 mins", calls[[#This Row],[Duration]]<=60, "30 to 60 mins", calls[[#This Row],[Duration]]<=120, "1 to 2 hours", TRUE, "More than 2 hours")} -> 1 to 2 hours | L11: =ROUND(calls[[#This Row],[Satisfaction Rating]],0) -> 4 | Q11: C0008 | R11: Female | S11: 42 | T11: Cleveland
B12: Call_7279 | C12: C0005 | D12: 31 | E12: R02 | F12: 44929 | G12: 135 | H12: 3.6 | I12: =IF(MONTH(calls[[#This Row],[Date of Call]])<=6, YEAR(calls[[#This Row],[Date of Call]]), YEAR(calls[[#This Row],[Date of Call]])+1) -> 2023 | J12: =TEXT(calls[[#This Row],[Date of Call]],"DDDD") -> Tuesday | K12: {=_xlfn.IFS(calls[[#This Row],[Duration]]<=10,"Under 10 mins", calls[[#This Row],[Duration]]<=30, "10 to 30 mins", calls[[#This Row],[Duration]]<=60, "30 to 60 mins", calls[[#This Row],[Duration]]<=120, "1 to 2 hours", TRUE, "More than 2 hours")} -> 30 to 60 mins | L12: =ROUND(calls[[#This Row],[Satisfaction Rating]],0) -> 4 | Q12: C0009 | R12: Female | S12: 25 | T12: Columbus
B13: Call_7280 | C13: C0010 | D13: 44 | E13: R03 | F13: 44929 | G13: 105 | H13: 2.9 | I13: =IF(MONTH(calls[[#This Row],[Date of Call]])<=6, YEAR(calls[[#This Row],[Date of Call]]), YEAR(calls[[#This Row],[Date of Call]])+1) -> 2023 | J13: =TEXT(calls[[#This Row],[Date of Call]],"DDDD") -> Tuesday | K13: {=_xlfn.IFS(calls[[#This Row],[Duration]]<=10,"Under 10 mins", calls[[#This Row],[Duration]]<=30, "10 to 30 mins", calls[[#This Row],[Duration]]<=60, "30 to 60 mins", calls[[#This Row],[Duration]]<=120, "1 to 2 hours", TRUE, "More than 2 hours")} -> 30 to 60 mins | L13: =ROUND(calls[[#This Row],[Satisfaction Rating]],0) -> 3 | Q13: C0010 | R13: Female | S13: 30 | T13: Cleveland
B14: Call_7281 | C14: C0011 | D14: 102 | E14: R02 | F14: 44929 | G14: 69 | H14: 4.9 | I14: =IF(MONTH(calls[[#This Row],[Date of Call]])<=6, YEAR(calls[[#This Row],[Date of Call]]), YEAR(calls[[#This Row],[Date of Call]])+1) -> 2023 | J14: =TEXT(calls[[#This Row],[Date of Call]],"DDDD") -> Tuesday | K14: {=_xlfn.IFS(calls[[#This Row],[Duration]]<=10,"Under 10 mins", calls[[#This Row],[Duration]]<=30, "10 to 30 mins", calls[[#This Row],[Duration]]<=60, "30 to 60 mins", calls[[#This Row],[Duration]]<=120, "1 to 2 hours", TRUE, "More than 2 hours")} -> 1 to 2 hours | L14: =ROUND(calls[[#This Row],[Satisfaction Rating]],0) -> 5 | Q14: C0011 | R14: Female | S14: 30 | T14: Cincinnati
B15: Call_7282 | C15: C0013 | D15: 135 | E15: R05 | F15: 44929 | G15: 46 | H15: 3.4 | I15: =IF(MONTH(calls[[#This Row],[Date of Call]])<=6, YEAR(calls[[#This Row],[Date of Call]]), YEAR(calls[[#This Row],[Date of Call]])+1) -> 2023 | J15: =TEXT(calls[[#This Row],[Date of Call]],"DDDD") -> Tuesday | K15: {=_xlfn.IFS(calls[[#This Row],[Duration]]<=10,"Under 10 mins", calls[[#This Row],[Duration]]<=30, "10 to 30 mins", calls[[#This Row],[Duration]]<=60, "30 to 60 mins", calls[[#This Row],[Duration]]<=120, "1 to 2 hours", TRUE, "More than 2 hours")} -> More than 2 hours | L15: =ROUND(calls[[#This Row],[Satisfaction Rating]],0) -> 3 | Q15: C0012 | R15: Female | S15: 28 | T15: Cincinnati
... B18: Call_7285 | C18: C0013 | D18: 48 | E18: R01 | F18: 44930 | G18: 68 | H18: 4.9 | I18: =IF(MONTH(calls[[#This Row],[Date of Call]])<=6, YEAR(calls[[#This Row],[Date of Call]]), YEAR(calls[[#This Row],[Date of Call]])+1) -> 2023 | J18: =TEXT(calls[[#This Row],[Date of Call]],"DDDD") -> Wednesday | K18: {=_xlfn.IFS(calls[[#This Row],[Duration]]<=10,"Under 10 mins", calls[[#This Row],[Duration]]<=30, "10 to 30 mins", calls[[#This Row],[Duration]]<=60, "30 to 60 mins", calls[[#This Row],[Duration]]<=120, "1 to 2 hours", TRUE, "More than 2 hours")} -> 30 to 60 mins | L18: =ROUND(calls[[#This Row],[Satisfaction Rating]],0) -> 5 | Q18: C0015 | R18: Female | S18: 43 | T18: Cleveland
B19: Call_7286 | C19: C0010 | D19: 176 | E19: R05 | F19: 44931 | G19: 24 | H19: 4.8 | I19: =IF(MONTH(calls[[#This Row],[Date of Call]])<=6, YEAR(calls[[#This Row],[Date of Call]]), YEAR(calls[[#This Row],[Date of Call]])+1) -> 2023 | J19: =TEXT(calls[[#This Row],[Date of Call]],"DDDD") -> Thursday | K19: {=_xlfn.IFS(calls[[#This Row],[Duration]]<=10,"Under 10 mins", calls[[#This Row],[Duration]]<=30, "10 to 30 mins", calls[[#This Row],[Duration]]<=60, "30 to 60 mins", calls[[#This Row],[Duration]]<=120, "1 to 2 hours", TRUE, "More than 2 hours")} -> More than 2 hours | L19: =ROUND(calls[[#This Row],[Satisfaction Rating]],0) -> 5
B20: Call_7287 | C20: C0010 | D20: 99 | E20: R01 | F20: 44931 | G20: 195 | H20: 3.9 | I20: =IF(MONTH(calls[[#This Row],[Date of Call]])<=6, YEAR(calls[[#This Row],[Date of Call]]), YEAR(calls[[#This Row],[Date of Call]])+1) -> 2023 | J20: =TEXT(calls[[#This Row],[Date of Call]],"DDDD") -> Thursday | K20: {=_xlfn.IFS(calls[[#This Row],[Duration]]<=10,"Under 10 mins", calls[[#This Row],[Duration]]<=30, "10 to 30 mins", calls[[#This Row],[Duration]]<=60, "30 to 60 mins", calls[[#This Row],[Duration]]<=120, "1 to 2 hours", TRUE, "More than 2 hours")} -> 1 to 2 hours | L20: =ROUND(calls[[#This Row],[Satisfaction Rating]],0) -> 4
B21: Call_7288 | C21: C0009 | D21: 28 | E21: R03 | F21: 44931 | G21: 28 | H21: 3.8 | I21: =IF(MONTH(calls[[#This Row],[Date of Call]])<=6, YEAR(calls[[#This Row],[Date of Call]]), YEAR(calls[[#This Row],[Date of Call]])+1) -> 2023 | J21: =TEXT(calls[[#This Row],[Date of Call]],"DDDD") -> Thursday | K21: {=_xlfn.IFS(calls[[#This Row],[Duration]]<=10,"Under 10 mins", calls[[#This Row],[Duration]]<=30, "10 to 30 mins", calls[[#This Row],[Duration]]<=60, "30 to 60 mins", calls[[#This Row],[Duration]]<=120, "1 to 2 hours", TRUE, "More than 2 hours")} -> 10 to 30 mins | L21: =ROUND(calls[[#This Row],[Satisfaction Rating]],0) -> 4
B22: Call_7289 | C22: C0007 | D22: 54 | E22: R02 | F22: 44931 | G22: 170 | H22: 4.3 | I22: =IF(MONTH(calls[[#This Row],[Date of Call]])<=6, YEAR(calls[[#This Row],[Date of Call]]), YEAR(calls[[#This Row],[Date of Call]])+1) -> 2023 | J22: =TEXT(calls[[#This Row],[Date of Call]],"DDDD") -> Thursday | K22: {=_xlfn.IFS(calls[[#This Row],[Duration]]<=10,"Under 10 mins", calls[[#This Row],[Duration]]<=30, "10 to 30 mins", calls[[#This Row],[Duration]]<=60, "30 to 60 mins", calls[[#This Row],[Duration]]<=120, "1 to 2 hours", TRUE, "More than 2 hours")} -> 30 to 60 mins | L22: =ROUND(calls[[#This Row],[Satisfaction Rating]],0) -> 4
B23: Call_7290 | C23: C0006 | D23: 48 | E23: R05 | F23: 44932 | G23: 30 | H23: 4.4 | I23: =IF(MONTH(calls[[#This Row],[Date of Call]])<=6, YEAR(calls[[#This Row],[Date of Call]]), YEAR(calls[[#This Row],[Date of Call]])+1) -> 2023 | J23: =TEXT(calls[[#This Row],[Date of Call]],"DDDD") -> Friday | K23: {=_xlfn.IFS(calls[[#This Row],[Duration]]<=10,"Under 10 mins", calls[[#This Row],[Duration]]<=30, "10 to 30 mins", calls[[#This Row],[Duration]]<=60, "30 to 60 mins", calls[[#This Row],[Duration]]<=120, "1 to 2 hours", TRUE, "More than 2 hours")} -> 30 to 60 mins | L23: =ROUND(calls[[#This Row],[Satisfaction Rating]],0) -> 4
B24: Call_7291 | C24: C0004 | D24: 128 | E24: R05 | F24: 44932 | G24: 72 | H24: 5 | I24: =IF(MONTH(calls[[#This Row],[Date of Call]])<=6, YEAR(calls[[#This Row],[Date of Call]]), YEAR(calls[[#This Row],[Date of Call]])+1) -> 2023 | J24: =TEXT(calls[[#This Row],[Date of Call]],"DDDD") -> Friday | K24: {=_xlfn.IFS(calls[[#This Row],[Duration]]<=10,"Under 10 mins", calls[[#This Row],[Duration]]<=30, "10 to 30 mins", calls[[#This Row],[Duration]]<=60, "30 to 60 mins", calls[[#This Row],[Duration]]<=120, "1 to 2 hours", TRUE, "More than 2 hours")} -> More than 2 hours | L24: =ROUND(calls[[#This Row],[Satisfaction Rating]],0) -> 5
B25: Call_7292 | C25: C0004 | D25: 38 | E25: R04 | F25: 44933 | G25: 92 | H25: 4.9 | I25: =IF(MONTH(calls[[#This Row],[Date of Call]])<=6, YEAR(calls[[#This Row],[Date of Call]]), YEAR(calls[[#This Row],[Date of Call]])+1) -> 2023 | J25: =TEXT(calls[[#This Row],[Date of Call]],"DDDD") -> Saturday | K25: {=_xlfn.IFS(calls[[#This Row],[Duration]]<=10,"Under 10 mins", calls[[#This Row],[Duration]]<=30, "10 to 30 mins", calls[[#This Row],[Duration]]<=60, "30 to 60 mins", calls[[#This Row],[Duration]]<=120, "1 to 2 hours", TRUE, "More than 2 hours")} -> 30 to 60 mins | L25: =ROUND(calls[[#This Row],[Satisfaction Rating]],0) -> 5
B26: Call_7293 | C26: C0003 | D26: 67 | E26: R04 | F26: 44934 | G26: 165 | H26: 4.5 | I26: =IF(MONTH(calls[[#This Row],[Date of Call]])<=6, YEAR(calls[[#This Row],[Date of Call]]), YEAR(calls[[#This Row],[Date of Call]])+1) -> 2023 | J26: =TEXT(calls[[#This Row],[Date of Call]],"DDDD") -> Sunday | K26: {=_xlfn.IFS(calls[[#This Row],[Duration]]<=10,"Under 10 mins", calls[[#This Row],[Duration]]<=30, "10 to 30 mins", calls[[#This Row],[Duration]]<=60, "30 to 60 mins", calls[[#This Row],[Duration]]<=120, "1 to 2 hours", TRUE, "More than 2 hours")} -> 1 to 2 hours | L26: =ROUND(calls[[#This Row],[Satisfaction Rating]],0) -> 5
B27: Call_7294 | C27: C0015 | D27: 58 | E27: R02 | F27: 44934 | G27: 140 | H27: 2.1 | I27: =IF(MONTH(calls[[#This Row],[Date of Call]])<=6, YEAR(calls[[#This Row],[Date of Call]]), YEAR(calls[[#This Row],[Date of Call]])+1) -> 2023 | J27: =TEXT(calls[[#This Row],[Date of Call]],"DDDD") -> Sunday | K27: {=_xlfn.IFS(calls[[#This Row],[Duration]]<=10,"Under 10 mins", calls[[#This Row],[Duration]]<=30, "10 to 30 mins", calls[[#This Row],[Duration]]<=60, "30 to 60 mins", calls[[#This Row],[Duration]]<=120, "1 to 2 hours", TRUE, "More than 2 hours")} -> 30 to 60 mins | L27: =ROUND(calls[[#This Row],[Satisfaction Rating]],0) -> 2
B28: Call_7295 | C28: C0010 | D28: 54 | E28: R01 | F28: 44934 | G28: 111 | H28: 3.3 | I28: =IF(MONTH(calls[[#This Row],[Date of Call]])<=6, YEAR(calls[[#This Row],[Date of Call]]), YEAR(calls[[#This Row],[Date of Call]])+1) -> 2023 | J28: =TEXT(calls[[#This Row],[Date of Call]],"DDDD") -> Sunday | K28: {=_xlfn.IFS(calls[[#This Row],[Duration]]<=10,"Under 10 mins", calls[[#This Row],[Duration]]<=30, "10 to 30 mins", calls[[#This Row],[Duration]]<=60, "30 to 60 mins", calls[[#This Row],[Duration]]<=120, "1 to 2 hours", TRUE, "More than 2 hours")} -> 30 to 60 mins | L28: =ROUND(calls[[#This Row],[Satisfaction Rating]],0) -> 3
B29: Call_7296 | C29: C0012 | D29: 28 | E29: R05 | F29: 44935 | G29: 63 | H29: 4.1 | I29: =IF(MONTH(calls[[#This Row],[Date of Call]])<=6, YEAR(calls[[#This Row],[Date of Call]]), YEAR(calls[[#This Row],[Date of Call]])+1) -> 2023 | J29: =TEXT(calls[[#This Row],[Date of Call]],"DDDD") -> Monday | K29: {=_xlfn.IFS(calls[[#This Row],[Duration]]<=10,"Under 10 mins", calls[[#This Row],[Duration]]<=30, "10 to 30 mins", calls[[#This Row],[Duration]]<=60, "30 to 60 mins", calls[[#This Row],[Duration]]<=120, "1 to 2 hours", TRUE, "More than 2 hours")} -> 10 to 30 mins | L29: =ROUND(calls[[#This Row],[Satisfaction Rating]],0) -> 4
B30: Call_7297 | C30: C0002 | D30: 73 | E30: R05 | F30: 44935 | G30: 80 | H30: 4.2 | I30: =IF(MONTH(calls[[#This Row],[Date of Call]])<=6, YEAR(calls[[#This Row],[Date of Call]]), YEAR(calls[[#This Row],[Date of Call]])+1) -> 2023 | J30: =TEXT(calls[[#This Row],[Date of Call]],"DDDD") -> Monday | K30: {=_xlfn.IFS(calls[[#This Row],[Duration]]<=10,"Under 10 mins", calls[[#This Row],[Duration]]<=30, "10 to 30 mins", calls[[#This Row],[Duration]]<=60, "30 to 60 mins", calls[[#This Row],[Duration]]<=120, "1 to 2 hours", TRUE, "More than 2 hours")} -> 1 to 2 hours | L30: =ROUND(calls[[#This Row],[Satisfaction Rating]],0) -> 4
... B1003: Call_8270 | C1003: C0009 | D1003: 114 | E1003: R01 | F1003: 45291 | G1003: 40 | H1003: 3.9 | I1003: =IF(MONTH(calls[[#This Row],[Date of Call]])<=6, YEAR(calls[[#This Row],[Date of Call]]), YEAR(calls[[#This Row],[Date of Call]])+1) -> 2024 | J1003: =TEXT(calls[[#This Row],[Date of Call]],"DDDD") -> Sunday | K1003: {=_xlfn.IFS(calls[[#This Row],[Duration]]<=10,"Under 10 mins", calls[[#This Row],[Duration]]<=30, "10 to 30 mins", calls[[#This Row],[Duration]]<=60, "30 to 60 mins", calls[[#This Row],[Duration]]<=120, "1 to 2 hours", TRUE, "More than 2 hours")} -> 1 to 2 hours | L1003: =ROUND(calls[[#This Row],[Satisfaction Rating]],0) -> 4

Sheet Customer Centre Report
O19: {=pivots!B96:F96} -> R01 | P19: R02 | Q19: R03 | R19: R04 | S19: R05 | T19: TOTAL
N20: {=IF(pivots!A97:G114="","",pivots!A97:G114)} -> Cincinnati | O20: 5483 | P20: 6014 | Q20: 4970 | R20: 3495 | S20: 6099 | T20: 26061
N21: C0003 | O21: 891 | P21: 1332 | Q21: 1282 | R21: 739 | S21: 560 | T21: 4804
N22: C0004 | O22: 1991 | P22: 1886 | Q22: 1206 | R22: 884 | S22: 1722 | T22: 7689
N23: C0011 | O23: 1163 | P23: 1180 | Q23: 1616 | R23: 1043 | S23: 1747 | T23: 6749
N24: C0012 | O24: 1438 | P24: 1616 | Q24: 866 | R24: 829 | S24: 2070 | T24: 6819
N25: Cleveland | O25: 7024 | P25: 7030 | Q25: 8482 | R25: 7379 | S25: 7934 | T25: 37849
N26: C0002 | O26: 1233 | P26: 223 | Q26: 1680 | R26: 990 | S26: 1508 | T26: 5634
N27: C0007 | O27: 1598 | P27: 1907 | Q27: 869 | R27: 1426 | S27: 1416 | T27: 7216
N28: C0008 | O28: 900 | P28: 1016 | Q28: 960 | R28: 940 | S28: 1193 | T28: 5009
N29: C0010 | O29: 900 | P29: 1470 | Q29: 1617 | R29: 1314 | S29: 941 | T29: 6242
N30: C0013 | O30: 1255 | P30: 516 | Q30: 1874 | R30: 1863 | S30: 1722 | T30: 7230
N31: C0015 | O31: 1138 | P31: 1898 | Q31: 1482 | R31: 846 | S31: 1154 | T31: 6518
N32: Columbus | O32: 5908 | P32: 7537 | Q32: 7420 | R32: 5777 | S32: 6071 | T32: 32713
K33: =pivots!H84 -> %of calls:19% | N33: C0001 | O33: 1655 | P33: 805 | Q33: 2263 | R33: 987 | S33: 1075 | T33: 6785
K34: =pivots!H85 -> call rank:5 | N34: C0005 | O34: 1104 | P34: 2280 | Q34: 1445 | R34: 1722 | S34: 1196 | T34: 7747
K35: =pivots!H86 -> Amount rank:5 | N35: C0006 | O35: 372 | P35: 1818 | Q35: 1346 | R35: 1156 | S35: 1484 | T35: 6176
N36: C0009 | O36: 1415 | P36: 1271 | Q36: 1214 | R36: 1135 | S36: 1566 | T36: 6601
N37: C0014 | O37: 1362 | P37: 1363 | Q37: 1152 | R37: 777 | S37: 750 | T37: 5404

Sheet Assets
E2: Rep ID | F2: Rep Image
E3: R01 | F3: #VALUE!
E4: R02 | F4: #VALUE!
E5: R03 | F5: #VALUE!
E6: R04 | F6: #VALUE!
E7: R05 | F7: #VALUE!
